Workbook

Sheet Dashboard
B1: SAKARYA PROJECT - INSPECTION & TEST PLAN — PIPE PRODUCTION TRACKING
B2: Input | C2: =E4 -> 170
B3: Seq. n° | C3: ITP Step | D3: Section | E3: Count | F3: Yield vs Input | G3: Loss vs Input | H3: Cumul. Loss | I3: Remarks
B4: 1 | C4: Incoming Plate | D4: Forming | E4: =Pivot!J7 -> 170 | F4: =IF(E4="N/A","",E4/170) -> 1 | G4: =170-E4 -> 0 | H4: =170-E4 -> 0
B5: 2 | C5: Pipe Forming | D5: Forming | E5: =Pivot!J8 -> 170 | F5: =IF(E5="N/A","",E5/170) -> 1 | G5: =170-E5 -> 0 | H5: =170-E5 -> 0
B6: 3 | C6: Tack Welding | D6: Forming | E6: =Pivot!J9 -> 170 | F6: =IF(E6="N/A","",E6/170) -> 1 | G6: =170-E6 -> 0 | H6: =170-E6 -> 0
B7: 4 | C7: ID SAWL | D7: Forming | E7: =Pivot!J10 -> 170 | F7: =IF(E7="N/A","",E7/170) -> 1 | G7: =170-E7 -> 0 | H7: =170-E7 -> 0
B8: 5 | C8: OD SAWL | D8: Forming | E8: =Pivot!J11 -> 170 | F8: =IF(E8="N/A","",E8/170) -> 1 | G8: =170-E8 -> 0 | H8: =170-E8 -> 0
B9: 6 | C9: AUT1 | D9: Welding & NDT | E9: =Pivot!J12 -> 170 | F9: =IF(E9="N/A","",E9/170) -> 1 | G9: =170-E9 -> 0 | H9: =170-E9 -> 0
B10: 7 | C10: Fluoroscopic | D10: Welding & NDT | E10: =Pivot!J13 -> 12 | F10: =IF(E10="N/A","",E10/170) -> 0.070588235 | G10: =170-E10 -> 158 | H10: =170-E10 -> 158
B11: 8 | C11: Welding Repair | D11: Welding & NDT | E11: =Pivot!J14 -> 4 | F11: =IF(E11="N/A","",E11/170) -> 0.023529412 | G11: 4 | H11: 4
B12: 9 | C12: MCE1 | D12: Mechanical | E12: =Pivot!J15 -> 164 | F12: =IF(E12="N/A","",E12/170) -> 0.96470588 | G12: =170-E12 -> 6 | H12: =170-E12 -> 6
B13: 10 | C13: MCE2 | D13: Mechanical | E13: =Pivot!J16 -> 0 | F13: — | G13: — | H13: —
B14: 11 | C14: MCE Inspection | D14: Mechanical | E14: =Pivot!J17 -> 164 | F14: =IF(E14="N/A","",E14/170) -> 0.96470588 | G14: =170-E14 -> 6 | H14: =170-E14 -> 6
B15: 12 | C15: Straightness Re-work | D15: Mechanical | E15: =Pivot!J18 -> 6 | F15: — | G15: — | H15: —
B16: 13 | C16: Hydro Test | D16: Testing | E16: =Pivot!J19 -> 158 | F16: =IF(E16="N/A","",E16/170) -> 0.92941176 | G16: =170-E16 -> 12 | H16: =170-E16 -> 12
B17: 14 | C17: AUT2 | D17: Testing | E17: =Pivot!J20 -> 0 | F17: — | G17: — | H17: —
B18: 15 | C18: Phase Arr. | D18: Testing | E18: =Pivot!J21 -> 158 | F18: =IF(E18="N/A","",E18/170) -> 0.92941176 | G18: =170-E18 -> 12 | H18: =170-E18 -> 12
B19: 16 | C19: MUT | D19: Testing | E19: =Pivot!J22 -> 158 | F19: =IF(E19="N/A","",E19/170) -> 0.92941176 | G19: =170-E19 -> 12 | H19: =170-E19 -> 12
B20: 17 | C20: End UT | D20: Testing | E20: =Pivot!J23 -> 157 | F20: =IF(E20="N/A","",E20/170) -> 0.92352941 | G20: =170-E20 -> 13 | H20: =170-E20 -> 13
B21: 18 | C21: X-Ray | D21: Testing | E21: =Pivot!J24 -> 156 | F21: =IF(E21="N/A","",E21/170) -> 0.91764706 | G21: =170-E21 -> 14 | H21: =170-E21 -> 14
B22: 19 | C22: OoR Pipe Body | D22: Dimensional & Final | E22: =Pivot!J25 -> 156 | F22: =IF(E22="N/A","",E22/170) -> 0.91764706 | G22: =170-E22 -> 14 | H22: =170-E22 -> 14
B23: 20 | C23: Dimensional 1 | D23: Dimensional & Final | E23: =Pivot!J26 -> 150 | F23: =IF(E23="N/A","",E23/170) -> 0.88235294 | G23: =170-E23 -> 20 | H23: =170-E23 -> 20
B24: 21 | C24: Dimensional 2 | D24: Dimensional & Final | E24: =Pivot!J27 -> 149 | F24: =IF(E24="N/A","",E24/170) -> 0.87647059 | G24: =170-E24 -> 21 | H24: =170-E24 -> 21
B25: 22 | C25: MPI | D25: Dimensional & Final | E25: =Pivot!J28 -> 149 | F25: =IF(E25="N/A","",E25/170) -> 0.87647059 | G25: =170-E25 -> 21 | H25: =170-E25 -> 21
B26: 23 | C26: UT DHC | D26: Dimensional & Final | E26: =Pivot!J29 -> 147 | F26: =IF(E26="N/A","",E26/170) -> 0.86470588 | G26: =170-E26 -> 23 | H26: =170-E26 -> 23
B27: 24 | C27: Final Mark & Weigh | D27: Dimensional & Final | E27: =Pivot!J30 -> 149 | F27: =IF(E27="N/A","",E27/170) -> 0.87647059 | G27: =170-E27 -> 21 | H27: =170-E27 -> 21
B30: SUMMARY
B31: Total Pipes | F31: =E4 -> 170
B32: Total pipes Accepted | F32: =E27 -> 149
B33: Overall Status % | F33: =F32/F31 -> 0.87647059
B34: Welding Repair | F34: 47

Sheet MPQT - WPQT
A1: Overview MPQT / WPQT SAWL Line Pipe - Lab Tests Control Table SAKARYA PROJECT
A2: OD X WT (in X in) | B2: WPS Nº | C2: Pipe Nº | D2: Heat N° | E2: Tenaris Labs Report | F2: Chemical Compos. Analysis | H2: Tensile Tests | Q2: Transversal Compression Test | S2: BM CVN Impact Testing -30°C | U2: CVN Impact Testing of the Weld Seam @ -30°C | AH2: CVN Impact Testing Transition Curve Base Metal @ +20°C to -120°C | AJ2: Drop Weight Tear Testing (DWTT) | AL2: CTOD (AF) | AO2: CTOD (AC) | AR2: Grain Size BM | AS2: Guided Bend Tests | AV2: VicKers Hardness Tests | AY2: Macrographic Test | AZ2: Flux Humidity (Karl Fischer) | BA2: Ring Splitting Test | BC2: HIC | BE2: SSC | BG2: Remarks
F3: BM | G3: WM | H3: Longitudinal BM | I3: Longitudinal BM (Coated) | J3: Transversal BM | K3: Transversal BM (Coated) | L3: Transversal WM | M3: Transversal WM (DNV) | N3: Transversal WM (Coated) | O3: ID and OD All Weld | P3: All Weld (Coated) | Q3: Without Inline Heat Treatment | R3: Inline Heat Treatment (Coated) | S3: AF | T3: Coated | U3: OD Weld Metal | V3: OD Weld FL | W3: OD Weld FL +2mm | X3: OD Weld FL +5mm | Y3: Root Weld Metal | Z3: Root Weld FL | AA3: Root Weld FL +2mm | AB3: Root Weld FL +5mm | AC3: ID Weld Metal | AD3: ID Weld FL | AE3: ID Weld FL +2mm | AF3: ID Weld FL +5mm | AG3: WM (Coated) | AH3: AF | AI3: AF (Aged) | AJ3: AF | AK3: Transition Curve | AL3: BM | AM3: WM | AN3: HAZ | AO3: BM | AP3: WM | AQ3: HAZ | AS3: OD | AT3: ID | AU3: Side | AV3: BM | AW3: HAZ | AX3: WM | AY3: Interpenetration | AZ3: WPQT | BA3: AF | BB3: AC | BC3: BM | BD3: WM | BE3: BM | BF3: WM
F4: 1/Pipe | H4: All | I4: All | J4: All | K4: All | L4: All | M4: WPQT Pipes | N4: All | O4: All | P4: All | Q4: All | S4: All | U4: All | AH4: All | AJ4: All | AL4: All | AO4: All | AR4: All | AS4: All | AV4: All | AY4: All | BA4: All | BB4: All | BC4: All
A5: 24 x 1.268 | B5: 3973 | C5: 26.4.002096 (AF) | D5: 974058.V | F5: IR-05 | G5: IR-05 | H5: IR-05 | I5: N/A | J5: IR-05 | K5: N/A | L5: IR-05 | M5: N/A | N5: N/A | O5: IR-05 | P5: N/A | Q5: IR-07 | R5: N/A | S5: IR-05 | T5: N/A | U5: IR-05 | V5: IR-05 | W5: IR-05 | X5: IR-05 | Y5: IR-05 | Z5: IR-05 | AA5: IR-05 | AB5: IR-05 | AC5: IR-05 | AD5: IR-05 & IR-08 | AE5: IR-05 | AF5: IR-05 | AG5: N/A | AH5: IR-08 | AI5: IR-08 | AJ5: IR-06 | AK5: IR-10 | AL5: IR-07 | AM5: IR-07 | AN5: IR-07 | AO5: N/A | AP5: N/A | AQ5: N/A | AR5: IR-09 | AS5: IR-05 | AT5: IR-05 | AU5: IR-05 | AV5: IR-05 | AW5: IR-05 | AX5: IR-05 | AY5: IR-05 | AZ5: Approved | BA5: IR-07 | BB5: N/A | BC5: IR-07 | BD5: IR-07 | BE5: IR-10 | BF5: IR-10 | BG5: *RT05/Rm Longitudinal BM Tensile at Border Line *CVN ID Fusino Line Rejected with single results 26J. *ReTest performed as per NCR-003 and approved for both Test
B6: 3973 | C6: 26.4.002097 (AF) | D6: 800223.V | F6: IR-05 | G6: IR-05 | H6: IR-05 & IR-08 | I6: N/A | J6: IR-05 | K6: N/A | L6: IR-05 | M6: IR-17 | N6: N/A | O6: IR-05 | P6: N/A | Q6: IR-07 | R6: N/A | S6: IR-05 | T6: N/A | U6: IR-05 | V6: IR-05 | W6: IR-05 | X6: IR-05 | Y6: IR-05 | Z6: IR-05 | AA6: IR-05 | AB6: IR-05 | AC6: IR-05 | AD6: IR-05 & IR-08 | AE6: IR-05 | AF6: IR-05 | AG6: N/A | AH6: IR-08 | AI6: IR-08 | AJ6: IR-06 | AK6: IR-10 | AL6: IR-07 | AM6: IR-07 | AN6: IR-07 | AO6: N/A | AP6: N/A | AQ6: N/A | AR6: IR-09 | AS6: IR-05 | AT6: IR-05 | AU6: IR-05 | AV6: IR-05 | AW6: IR-05 | AX6: IR-05 | AY6: IR-05 | AZ6: Approved | BA6: IR-07 | BB6: N/A | BC6: IR-07 | BD6: IR-07 | BE6: IR-10 | BF6: IR-10 | BG6: *RT05/Rm Longitudinal BM Tensile at Rejected *CVN ID Fusino Line Rejected with single results 29J *ReTest performed as per NCR-003 and approved for both Test
B7: 3973 | C7: 26.4.002098 (AF) | D7: 800223.V | F7: IR-05 | G7: IR-05 | H7: IR-05 | I7: N/A | J7: IR-05 | K7: N/A | L7: IR-05 | M7: N/A | N7: N/A | O7: IR-05 | P7: N/A | Q7: IR-07 | R7: N/A | S7: IR-05 | T7: N/A | U7: IR-05 | V7: IR-05 | W7: IR-05 | X7: IR-05 | Y7: IR-05 | Z7: IR-05 | AA7: IR-05 | AB7: IR-05 | AC7: IR-05 | AD7: IR-05 | AE7: IR-05 | AF7: IR-05 | AG7: N/A | AH7: IR-08 | AI7: IR-08 | AJ7: IR-06 | AK7: IR-10 | AL7: IR-07 | AM7: IR-07 | AN7: IR-07 | AO7: N/A | AP7: N/A | AQ7: N/A | AR7: IR-09 | AS7: IR-05 | AT7: IR-05 | AU7: IR-05 | AV7: IR-05 | AW7: IR-05 | AX7: IR-05 | AY7: IR-05 | AZ7: Approved | BA7: IR-07 | BB7: N/A | BC7: IR-07 | BD7: IR-07 | BE7: IR-10 | BF7: IR-10
B8: 3974 | C8: 26.4.002240 (AF) | D8: 974058.V | F8: IR-05 | G8: IR-05 | H8: IR-05 & IR-08 | I8: N/A | J8: IR-05 | K8: N/A | L8: IR-05 | M8: IR-17 | N8: N/A | O8: IR-05 | P8: N/A | Q8: IR-07 | R8: N/A | S8: IR-05 | T8: N/A | U8: IR-05 | V8: IR-05 | W8: IR-05 | X8: IR-05 | Y8: IR-05 | Z8: IR-05 | AA8: IR-05 | AB8: IR-05 | AC8: IR-05 | AD8: IR-05 | AE8: IR-05 | AF8: IR-05 | AG8: N/A | AH8: IR-08 | AI8: IR-08 | AJ8: IR-06 | AK8: IR-10 | AL8: IR-07 | AM8: IR-07 | AN8: IR-07 | AO8: N/A | AP8: N/A | AQ8: N/A | AR8: IR-09 | AS8: IR-05 | AT8: IR-05 | AU8: IR-05 | AV8: IR-05 | AW8: IR-05 | AX8: IR-05 | AY8: IR-05 | AZ8: Approved | BA8: IR-07 | BB8: N/A | BC8: IR-07 | BD8: IR-07 | BE8: IR-10 | BF8: IR-10 | BG8: *RT05/Rm Longitudinal BM Tensile at Rejected *ReTest performed as per NCR-003 and approved
B9: 3973 | C9: 26.4.002099 (AC) | D9: 800223.V | F9: N/A | G9: N/A | H9: N/A | I9: IR-13 | J9: N/A | K9: IR-13 | L9: N/A | M9: N/A | N9: IR-13 | O9: N/A | P9: IR-13 | Q9: N/A | R9: IR-14 | S9: N/A | T9: IR-14 | U9: N/A | V9: N/A | W9: N/A | X9: N/A | Y9: N/A | Z9: N/A | AA9: N/A | AB9: N/A | AC9: N/A | AD9: N/A | AE9: N/A | AF9: N/A | AG9: N/A | AH9: N/A | AI9: N/A | AJ9: N/A | AK9: N/A | AL9: N/A | AM9: N/A | AN9: N/A | AO9: IR-14 | AP9: IR-14 | AQ9: IR-14 | AR9: N/A | AS9: N/A | AT9: N/A | AU9: N/A | AV9: N/A | AW9: N/A | AX9: N/A | AY9: N/A | AZ9: Approved | BA9: N/A | BB9: IR-14 | BC9: N/A | BD9: N/A | BE9: N/A | BF9: N/A | BG9: RT0.5/Rm for “AS FABRICATES” MPQT is: 0.93 however for the “AS COATED” in the QCP is specifying Informative
B10: 3973 | C10: 26.4.002100 (AC) | D10: 800223.V | F10: N/A | G10: N/A | H10: N/A | I10: IR-13 | J10: N/A | K10: IR-13 | L10: N/A | M10: N/A | N10: IR-13 | O10: N/A | P10: IR-13 | Q10: N/A | R10: IR-14 | S10: N/A | T10: IR-14 | U10: N/A | V10: N/A | W10: N/A | X10: N/A | Y10: N/A | Z10: N/A | AA10: N/A | AB10: N/A | AC10: N/A | AD10: N/A | AE10: N/A | AF10: N/A | AG10: N/A | AH10: N/A | AI10: N/A | AJ10: N/A | AK10: N/A | AL10: N/A | AM10: N/A | AN10: N/A | AO10: IR-14 | AP10: IR-14 | AQ10: IR-14 | AR10: N/A | AS10: N/A | AT10: N/A | AU10: N/A | AV10: N/A | AW10: N/A | AX10: N/A | AY10: N/A | AZ10: Approved | BA10: N/A | BB10: IR-14 | BC10: N/A | BD10: N/A | BE10: N/A | BF10: N/A
B11: 3973 | C11: 26.4.002101 (AC) | D11: 974058.V | F11: N/A | G11: N/A | H11: N/A | I11: IR-13 | J11: N/A | K11: IR-13 | L11: N/A | M11: N/A | N11: IR-13 | O11: N/A | P11: IR-13 | Q11: N/A | R11: IR-14 | S11: N/A | T11: IR-14 | U11: N/A | V11: N/A | W11: N/A | X11: N/A | Y11: N/A | Z11: N/A | AA11: N/A | AB11: N/A | AC11: N/A | AD11: N/A | AE11: N/A | AF11: N/A | AG11: N/A | AH11: N/A | AI11: N/A | AJ11: N/A | AK11: N/A | AL11: N/A | AM11: N/A | AN11: N/A | AO11: IR-14 | AP11: IR-14 | AQ11: IR-14 | AR11: N/A | AS11: N/A | AT11: N/A | AU11: N/A | AV11: N/A | AW11: N/A | AX11: N/A | AY11: N/A | AZ11: Approved | BA11: N/A | BB11: IR-14 | BC11: N/A | BD11: N/A | BE11: N/A | BF11: N/A | BG11: RT0.5/Rm for “AS FABRICATES” MPQT is: 0.93 however for the “AS COATED” in the QCP is specifying Informative
B12: 3973 | C12: 26.4.002243 (AC) | D12: 974058.V | F12: N/A | G12: N/A | H12: N/A | I12: IR-13 | J12: N/A | K12: IR-13 | L12: N/A | M12: N/A | N12: IR-13 | O12: N/A | P12: IR-13 | Q12: N/A | R12: IR-14 | S12: N/A | T12: IR-14 | U12: N/A | V12: N/A | W12: N/A | X12: N/A | Y12: N/A | Z12: N/A | AA12: N/A | AB12: N/A | AC12: N/A | AD12: N/A | AE12: N/A | AF12: N/A | AG12: N/A | AH12: N/A | AI12: N/A | AJ12: N/A | AK12: N/A | AL12: N/A | AM12: N/A | AN12: N/A | AO12: IR-14 | AP12: IR-14 | AQ12: IR-14 | AR12: N/A | AS12: N/A | AT12: N/A | AU12: N/A | AV12: N/A | AW12: N/A | AX12: N/A | AY12: N/A | AZ12: Approved | BA12: N/A | BB12: IR-14 | BC12: N/A | BD12: N/A | BE12: N/A | BF12: N/A | BG12: RT0.5/Rm for “AS FABRICATES” MPQT is: 0.93 however for the “AS COATED” in the QCP is specifying Informative
A13: Repair Qualification
A14: 24 x 1.268 (STOP/START) | B14: WPS-3973 | C14: 26.4. 2128 (INT) | D14: 800232.V | U14: IR-19 | Y14: IR-19 | AC14: IR-19 | AD14: IR-19 | AE14: IR-19 | AR14: IR-19 | AV14: IR-18 | AW14: IR-18 | AX14: IR-18 | AY14: IR-18
C15: 26.4.2128 (EXT) | U15: IR-19 | V15: IR-19 | W15: IR-19 | Y15: IR-19 | AC15: IR-19 | AR15: IR-19 | AV15: IR-18 | AW15: IR-18 | AX15: IR-18 | AY15: IR-18
A16: OD 24 x 1.268 (rWPS) | B16: WPS-260 (SHALLOW) | C16: 26.4. 2128
B17: WPS-262 (DEEP)
A18: ID 24 x 1.268 (rWPS) | B18: WPS-260 (SHALLOW) | C18: 26.4. 2205 | D18: 800222.V
B19: WPS-262 (DEEP)

Sheet 24 X 1.268 OFF
A1: SAKARYA PROJECT - Overview Mass Production for SAWL Line Pipe - Lab Tests Control Table
A2: OD24in X WT1.268in
A3: OD X WT | B3: Pipe Nº | C3: Heat Plate N° | D3: Chemical Compos. Analysis | F3: Tensile Tests | J3: Transversal Compression Test | K3: BM CVN Impact Testing -30°C | L3: CVN Impact Testing of the Weld Seam @ -30°C | U3: Drop Weight Tear Testing (DWTT) | V3: Grain Size BM | W3: Guided Bend Tests | Y3: VicKers Hardness Tests | AB3: Macrographic Test | AC3: HIC | AE3: Remarks
D4: BM | E4: BM | F4: Longitudinal BM | G4: Transversal BM | H4: Transversal WM | I4: Transversal WM (Coated) | J4: Inline Heat Treatment | K4: AF | L4: WM OD | M4: WD ID | N4: WM Root | O4: FL OD | P4: FL ID | Q4: FL Root | R4: FL + 2 OD | S4: FL + 2 ID | T4: FL + 2 Root | U4: BM | W4: OD | X4: ID | Y4: BM | Z4: HAZ | AA4: WM | AB4: Interpenetration | AC4: BM | AD4: WM
D5: 1/Pipe | F5: 1/Heat | G5: 1/Heat | H5: 1/Heat | I5: All | J5: 4/Heat 20 1/Heat | K5: 1/Heat | L5: 1/Heat | U5: 1/Heat | V5: 1 / 5 Heats | W5: 1/Heat | Y5: 1/Heat | AB5: 1/Shift | AC5: 1 /Heat (first five Heat, than 1 / 10)
A6: 36 x 0.406 | B6: 11646 | C6: 780325 | D6: IR-06 | E6: IR-06 | F6: IR-11 | G6: IR-09 | H6: IR-09 | K6: IR-11 | L6: IR-11 | M6: IR-11 | N6: IR-11 | O6: IR-11 / IR-15 | P6: IR-11 | Q6: IR-11 | R6: IR-11 | S6: IR-11 | T6: IR-11 | U6: IR-09 | V6: IR-11 | W6: IR-09 | X6: IR-09 | Y6: IR-06 | Z6: IR-06 | AA6: IR-06 | AB6: IR-06 | AC6: IR-08 | AD6: IR-08 | AE6: CVN Failure at OD FL+2mm (NCR-004) - Re-test performed and approved
C7: 800222 | D7: IR-06 | E7: IR-09 | F7: IR-11 | G7: IR-09 | H7: IR-09 | K7: IR-11 | L7: IR-11 | M7: IR-11 | N7: IR-11 | O7: IR-11 / IR-15 | P7: IR-11 | Q7: IR-11 | R7: IR-11 | S7: IR-11 | T7: IR-11 | U7: IR-09 | V7: IR-11 | W7: IR-09 | X7: IR-09 | Y7: IR-06 | Z7: IR-06 | AA7: IR-06 | AB7: IR-06 | AC7: IR-08 | AD7: IR-08 | AE7: CVN Failure at Intersectio FL (NCR-004) - Re-test performed and approved
C8: 800229 | D8: IR-06 | E8: IR-09 | F8: IR-11 | G8: IR-09 | H8: IR-09 | K8: IR-11 | L8: IR-11 | M8: IR-11 | N8: IR-11 | O8: IR-11 / IR-15 | P8: IR-11 | Q8: IR-11 | R8: IR-11 | S8: IR-11 | T8: IR-11 | U8: IR-09 | V8: IR-11 | W8: IR-09 | X8: IR-09 | Y8: IR-06 | Z8: IR-06 | AA8: IR-06 | AB8: IR-06 | AC8: IR-08 | AD8: IR-08 | AE8: CVN Failure at Intersection, on the NCR-004 Tenaris have informed that the CVN specimen of Intersevtion WM, was with the notch on the wrong sectiom and it is a FL Re-test performed and approved
C9: 800232 | D9: IR-06 | E9: IR-09 | F9: IR-11 | G9: IR-09 | H9: IR-09 | K9: IR-11 | L9: IR-11 | M9: IR-11 | N9: IR-11 | O9: IR-11 | P9: IR-11 | Q9: IR-11 | R9: IR-11 | S9: IR-11 | T9: IR-11 | U9: IR-09 | V9: IR-11 | W9: IR-09 | X9: IR-09 | Y9: IR-06 | Z9: IR-06 | AA9: IR-06 | AB9: IR-06 | AC9: IR-08 | AD9: IR-08
C10: 800233 | D10: IR-06 | E10: IR-06 | F10: IR-11 | G10: IR-09 | H10: IR-09 | K10: IR-11 | L10: IR-11 | M10: IR-11 | N10: IR-11 | O10: IR-11 IR-15 IR-17 | P10: IR-11 | Q10: IR-11 | R10: IR-11 | S10: IR-11 | T10: IR-11 | U10: IR-09 | V10: IR-11 | W10: IR-09 | X10: IR-09 | Y10: IR-06 | Z10: IR-06 | AA10: IR-06 | AB10: IR-06 | AC10: IR-08 | AD10: IR-08 | AE10: CVN Failure at Intersectio ID and OD FL (NCR-004) - Re-test performed Rejected on the same pipe (26.4.2117). Retest Performed and approved in two addtional Pipes from the same Test unit and approved (26.4.2147 and 2152)
C11: 974062 | D11: IR-06 | E11: IR-06 | F11: IR-11 | G11: IR-09 | H11: IR-09 | K11: IR-11 | L11: IR-11 | M11: IR-11 | N11: IR-11 | O11: IR-11 | P11: IR-11 | Q11: IR-11 | R11: IR-11 | S11: IR-11 | T11: IR-11 | U11: IR-09 | V11: IR-11 | W11: IR-09 | X11: IR-09 | Y11: IR-06 | Z11: IR-06 | AA11: IR-06 | AB11: IR-06 | AC11: IR-08 | AD11: IR-08
C12: 780991
C13: 780992
C14: 780993
C15: 780995
C16: 781083
C17: 781283 | K17: IR-19 | L17: IR-19 | M17: IR-19 | N17: IR-19 | P17: IR-19 | R17: IR-19 | S17: IR-19 | T17: IR-19
C18: 781297 | D18: IR-19 | E18: IR-19 | K18: IR-19 | L18: IR-19 | M18: IR-19 | N18: IR-19 | O18: IR-19 | P18: IR-19 | Q18: IR-19 | R18: IR-19 | S18: IR-19 | T18: IR-19
C19: 800223
C20: 800943
C21: 800957
C22: 800958
C23: 800959
C24: 800965
C25: 800970
C26: 801169
C27: 801174
C28: 801198
C29: 801208 | D29: IR-19 | E29: IR-19 | K29: IR-19 | L29: IR-19 | M29: IR-19 | N29: IR-19 | O29: IR-19 | P29: IR-19 | Q29: IR-19 | R29: IR-19 | S29: IR-19 | T29: IR-19
C30: 801219 | D30: IR-19 | E30: IR-19 | K30: IR-19 | L30: IR-19 | M30: IR-19 | N30: IR-19 | O30: IR-19 | P30: IR-19 | Q30: IR-19 | R30: IR-19 | S30: IR-19 | T30: IR-19
C31: 974058
C32: 974992 | D32: IR-19 | K32: IR-19 | L32: IR-19 | N32: IR-19 | R32: IR-19 | T32: IR-19
C33: 975002 | D33: IR-19 | M33: IR-19 | O33: IR-19 | P33: IR-19 | Q33: IR-19 | S33: IR-19

Sheet PO5021701
A1: Totale | I1: =SUBTOTAL(103,Tabella1[Total Pipes]) -> 170 | N1: =SUBTOTAL(9,Tabella1[Pipe length2]) -> 11220838 | O1: =SUBTOTAL(103,Tabella1[Plate Entrance]) -> 908 | P1: =SUBTOTAL(103,Tabella1[Pipe Forming]) -> 713 | Q1: =SUBTOTAL(103,Tabella1[Tack Welding]) -> 708 | R1: =SUBTOTAL(103,Tabella1[ID SAWL]) -> 701 | S1: =SUBTOTAL(103,Tabella1[OD SAWL]) -> 679 | T1: =SUBTOTAL(103,Tabella1[AUT1 in House]) -> 672 | U1: =SUBTOTAL(103,Tabella1[Fluoroscopic/TOFD In House]) -> 13 | V1: =SUBTOTAL(103,Tabella1[Repair]) -> 18 | W1: =SUBTOTAL(103,Tabella1[MCE 1]) -> 412 | X1: =SUBTOTAL(103,Tabella1[MCE 2]) -> 632 | Y1: =SUBTOTAL(103,Tabella1[Straighness Re-work]) -> 5 | Z1: =SUBTOTAL(103,Tabella1[Hydrostatic Test]) -> 620 | AA1: =SUBTOTAL(103,Tabella1[Phase Array]) -> 573 | AB1: =SUBTOTAL(103,Tabella1[MUT]) -> 558 | AC1: =SUBTOTAL(103,Tabella1[Pipe End UT]) -> 547 | AD1: =SUBTOTAL(103,Tabella1[X-Ray]) -> 544 | AE1: =SUBTOTAL(103,Tabella1[OoR Pipe Body]) -> 536 | AF1: =SUBTOTAL(103,Tabella1[Dimensional 1]) -> 525 | AG1: =SUBTOTAL(103,Tabella1[Dimensional 2]) -> 337 | AH1: =SUBTOTAL(103,Tabella1[MPI]) -> 333 | AI1: =SUBTOTAL(103,Tabella1[Final Marking and Weighing]) -> 327 | AJ1: =SUBTOTAL(103,Tabella1[UT DHC]) -> 29
A2: Seq. N° | B2: Tenaris Batch | C2: Pipe Dimensional | D2: Pipe Std | E2: Pipe Number | F2: Heat Number | G2: Plate Number | H2: Pipe length | I2: Total Pipes | J2: Tenaris Lote | K2: Pipe N° | L2: Heat N° | M2: Plate N° | N2: Pipe length2 | O2: Plate Entrance | P2: Pipe Forming | Q2: Tack Welding | R2: ID SAWL | S2: OD SAWL | T2: AUT1 in House | U2: Fluoroscopic/TOFD In House | V2: Repair | W2: MCE 1 | X2: MCE 2 | Y2: Straighness Re-work | Z2: Hydrostatic Test | AA2: Phase Array | AB2: MUT | AC2: Pipe End UT | AD2: X-Ray | AE2: OoR Pipe Body | AF2: Dimensional 1 | AG2: Dimensional 2 | AH2: MPI | AI2: Final Marking and Weighing | AJ2: UT DHC
A3: 1 | B3: 5021701 | C3: 609.600mm / 32.200mm | D3: DNV-ST-F101-2021 x 450 SFDU | E3: 26.4.002086 | F3: 800229.V | G3: 112430/2.V | H3: 12350 | I3: 1 | J3: 5021601 | K3: 26.4.002179 | L3: 800223.V | M3: 112461/1.V | N3: 12400 | O3: EC | P3: PU | Q3: SEL | R3: SI | S3: SE | T3: U1 | W3: SMS | X3: EX2 | Y3: PDES | Z3: TH | AA3: UTPA | AB3: UTMAN | AC3: UE | AD3: RX | AE3: LIMAB | AF3: IF1 | AG3: IF2 | AH3: PM | AI3: BA
A4: 2 | B4: 5021701 | C4: 609.600mm / 32.200mm | D4: DNV-ST-F101-2021 x 450 SFDU | E4: 26.4.002211 | F4: 800222.V | G4: 112447/1.V | H4: 12450 | I4: 1 | J4: 5021601 | K4: 26.4.002113 | L4: 800229.V | M4: 112429/2.V | N4: 12400 | O4: EC | P4: PU | Q4: SEL | R4: SI | S4: SE | T4: U1 | W4: SMS | X4: EX2 | Y4: PDES | Z4: TH | AA4: UTPA | AB4: UTMAN | AC4: UE | AD4: RX | AE4: LIMAB | AF4: IF1 | AG4: IF2 | AH4: PM | AI4: BA
A5: 3 | B5: 5021701 | C5: 609.600mm / 32.200mm | D5: DNV-ST-F101-2021 x 450 SFDU | E5: 26.4.002085 | F5: 800229.V | G5: 112426/2.V | H5: 12380 | I5: 1 | J5: 5021601 | K5: 26.4.002090 | L5: 800229.V | M5: 112432/1.V | N5: 12330 | O5: EC | P5: PU | Q5: SEL | R5: SI | S5: SE | T5: U1 | W5: SMS | X5: EX2 | Y5: PDES | Z5: TH | AA5: UTPA | AB5: UTMAN | AC5: UE | AD5: RX | AE5: LIMAB | AF5: IF1 | AG5: IF2 | AH5: PM | AI5: BA
A6: 4 | B6: 5021701 | C6: 609.600mm / 32.200mm | D6: DNV-ST-F101-2021 x 450 SFDU | E6: 26.4.002089 | F6: 800229.V | G6: 112427/1.V | H6: 12470 | I6: 1 | J6: 5021601 | K6: 26.4.002170 | L6: 780325.V | M6: 112403/2.V | N6: 12400 | O6: EC | P6: PU | Q6: SEL | R6: SI | S6: SE | T6: U1 | W6: SMS | X6: EX2 | Y6: PDES | Z6: TH | AA6: UTPA | AB6: UTMAN | AC6: UE | AD6: RX | AE6: LIMAB | AF6: IF1 | AG6: IF2 | AH6: PM | AI6: BA
A7: 5 | B7: 5021701 | C7: 609.600mm / 32.200mm | D7: DNV-ST-F101-2021 x 450 SFDU | E7: 26.4.002090 | F7: 800229.V | G7: 112432/1.V | H7: 12360 | I7: 1 | J7: 5021601 | K7: 26.4.002238 | L7: 974058.V | M7: 112416/1.V | N7: 12400 | O7: EC | P7: PU | Q7: SEL | R7: SI | S7: SE | T7: U1 | W7: SMS | X7: EX2 | Y7: PDES | Z7: TH | AA7: UTPA | AB7: UTMAN | AC7: UE | AD7: RX | AE7: LIMAB | AF7: IF1 | AG7: IF2 | AH7: PM | AI7: BA
A8: 6 | B8: 5021701 | C8: 609.600mm / 32.200mm | D8: DNV-ST-F101-2021 x 450 SFDU | E8: 26.4.002147 | F8: 800233.V | G8: 112487/2.V | H8: 12460 | I8: 1 | J8: 5021701 | K8: 26.4.008021 | L8: 780995.V | M8: 118305/2.V | N8: 12460 | O8: EC | P8: PU | Q8: SEL | R8: SI | S8: SE | T8: U1 | X8: EX2 | Z8: TH | AA8: UTPA | AB8: UTMAN | AC8: UE | AD8: RX | AE8: LIMAB | AF8: IF1 | AG8: IF2 | AH8: PM
A9: 7 | B9: 5021701 | C9: 609.600mm / 32.200mm | D9: DNV-ST-F101-2021 x 450 SFDU | E9: 26.4.002092 | F9: 800229.V | G9: 112424/1.V | H9: 12360 | I9: 1 | J9: 5021701 | K9: 26.4.002087 | L9: 800229.V | M9: 112432/2.V | N9: 12020 | O9: EC | P9: PU | Q9: SEL | R9: SI | S9: SE | T9: U1 | W9: SMS | X9: EX2 | Z9: TH | AA9: UTPA | AB9: UTMAN | AC9: UE | AD9: RX | AE9: LIMAB | AF9: IF1 | AG9: IF2 | AH9: PM | AI9: BA
A10: 8 | B10: 5021701 | C10: 609.600mm / 32.200mm | D10: DNV-ST-F101-2021 x 450 SFDU | E10: 26.4.002088 | F10: 800229.V | G10: 112426/1.V | H10: 12430 | I10: 1 | J10: 5021701 | K10: 26.4.002194 | L10: 780325.V | M10: 112397/1.V | N10: 12440 | O10: EC | P10: PU | Q10: SEL | R10: SI | S10: SE | T10: U1 | W10: SMS | X10: EX2 | Z10: TH | AA10: UTPA | AB10: UTMAN | AC10: UE | AD10: RX | AE10: LIMAB | AF10: IF1 | AG10: IF2 | AH10: PM | AI10: BA
A11: 9 | B11: 5021701 | C11: 609.600mm / 32.200mm | D11: DNV-ST-F101-2021 x 450 SFDU | E11: 26.4.002094 | F11: 800229.V | G11: 112430/1.V | H11: 12470 | I11: 1 | J11: 5021701 | K11: 26.4.002089 | L11: 800229.V | M11: 112427/1.V | N11: 12470 | O11: EC | P11: PU | Q11: SEL | R11: SI | S11: SE | T11: U1 | V11: REP
A12: 10 | B12: 5021701 | C12: 609.600mm / 32.200mm | D12: DNV-ST-F101-2021 x 450 SFDU | E12: 26.4.002095 | F12: 974058.V | G12: 112411/1.V | H12: 12460 | I12: 1 | J12: 5021701 | K12: 26.4.002099 | L12: 800223.V | M12: 112459/1.V | N12: 12330 | O12: EC | P12: PU | Q12: SEL | R12: SI | S12: SE | T12: U1 | W12: SMS | X12: EX2 | Z12: TH | AA12: UTPA | AB12: UTMAN | AC12: UE | AD12: RX | AE12: LIMAB | AF12: IF1 | AG12: IF2 | AH12: PM | AI12: BA
A13: 11 | B13: 5021701 | C13: 609.600mm / 32.200mm | D13: DNV-ST-F101-2021 x 450 SFDU | E13: 26.4.002096 | F13: 974058.V | G13: 112412/2.V | H13: 12470 | I13: 1 | J13: 5021701 | K13: 26.4.002086 | L13: 800229.V | M13: 112430/2.V | N13: 12230 | O13: EC | P13: PU | Q13: SEL | R13: SI | S13: SE | T13: U1 | W13: SMS | X13: EX2 | Z13: TH | AA13: UTPA | AB13: UTMAN | AC13: UE | AD13: RX | AE13: LIMAB | AF13: IF1 | AG13: IF2 | AH13: PM | AI13: BA
A14: 12 | B14: 5021701 | C14: 609.600mm / 32.200mm | D14: DNV-ST-F101-2021 x 450 SFDU | E14: 26.4.002097 | F14: 800223.V | G14: 112460/1.V | H14: 12370 | I14: 1 | J14: 5021701 | K14: 26.4.007789 | L14: 781297.V | M14: 121336/2.V | N14: 12460 | O14: EC | P14: PU | Q14: SEL | R14: SI | S14: SE | T14: U1 | W14: SMS | X14: EX2 | Z14: TH | AA14: UTPA | AB14: UTMAN | AC14: UE | AD14: RX | AE14: LIMAB | AF14: IF1
A15: 13 | B15: 5021701 | C15: 609.600mm / 32.200mm | D15: DNV-ST-F101-2021 x 450 SFDU | E15: 26.4.002098 | F15: 800223.V | G15: 112459/2.V | H15: 12370 | I15: 1 | J15: 5021701 | K15: 26.4.002085 | L15: 800229.V | M15: 112426/2.V | N15: 12130 | O15: EC | P15: PU | Q15: SEL | R15: SI | S15: SE | T15: U1 | W15: SMS | X15: EX2 | Z15: TH | AA15: UTPA | AB15: UTMAN | AC15: UE | AD15: RX | AE15: LIMAB | AF15: IF1 | AG15: IF2 | AH15: PM | AI15: BA
A16: 14 | B16: 5021701 | C16: 609.600mm / 32.200mm | D16: DNV-ST-F101-2021 x 450 SFDU | E16: 26.4.002115 | F16: 800233.V | G16: 112488/2.V | H16: 12450 | I16: 1 | J16: 5021701 | K16: 26.4.002096 | L16: 974058.V | M16: 112412/2.V | N16: 12430 | O16: EC | P16: PU | Q16: SEL | R16: SI | S16: SE | T16: U1 | U16: FL | W16: SMS | X16: EX2 | Z16: TH | AA16: UTPA | AB16: UTMAN
A17: 15 | B17: 5021701 | C17: 609.600mm / 32.200mm | D17: DNV-ST-F101-2021 x 450 SFDU | E17: 26.4.002100 | F17: 800223.V | G17: 112460/2.V | H17: 12470 | I17: 1 | J17: 5021701 | K17: 26.4.002158 | L17: 780325.V | M17: 112407/2.V | N17: 12440 | O17: EC | P17: PU | Q17: SEL | R17: SI | S17: SE | T17: U1 | W17: SMS | X17: EX2 | Z17: TH | AA17: UTPA | AB17: UTMAN | AC17: UE | AD17: RX | AE17: LIMAB | AF17: IF1 | AG17: IF2 | AH17: PM | AI17: BA
A18: 16 | B18: 5021701 | C18: 609.600mm / 32.200mm | D18: DNV-ST-F101-2021 x 450 SFDU | E18: 26.4.002101 | F18: 974058.V | G18: 112412/1.V | H18: 12460 | I18: 1 | J18: 5021701 | K18: 26.4.002097 | L18: 800223.V | M18: 112460/1.V | N18: 12300 | O18: EC | P18: PU | Q18: SEL | R18: SI | S18: SE | T18: U1 | U18: FL | W18: SMS | X18: EX2 | Z18: TH | AA18: UTPA | AB18: UTMAN
A19: 17 | B19: 5021701 | C19: 609.600mm / 32.200mm | D19: DNV-ST-F101-2021 x 450 SFDU | E19: 26.4.002102 | F19: 974058.V | G19: 112411/2.V | H19: 12460 | I19: 1 | J19: 5021701 | K19: 26.4.002098 | L19: 800223.V | M19: 112459/2.V | N19: 12340 | O19: EC | P19: PU | Q19: SEL | R19: SI | S19: SE | T19: U1 | U19: FL | W19: SMS | X19: EX2 | Z19: TH | AA19: UTPA | AB19: UTMAN
A20: 18 | B20: 5021701 | C20: 609.600mm / 32.200mm | D20: DNV-ST-F101-2021 x 450 SFDU | E20: 26.4.002103 | F20: 800229.V | G20: 112427/2.V | H20: 12440 | I20: 1 | J20: 5021701 | K20: 26.4.002125 | L20: 800232.V | M20: 112442/1.V | N20: 12430 | O20: EC | P20: PU | Q20: SEL | R20: SI | S20: SE | T20: U1 | W20: SMS | X20: EX2 | Z20: TH | AA20: UTPA | AB20: UTMAN | AC20: UE | AD20: RX | AE20: LIMAB | AF20: IF1 | AG20: IF2 | AH20: PM | AI20: BA
A21: 19 | B21: 5021701 | C21: 609.600mm / 32.200mm | D21: DNV-ST-F101-2021 x 450 SFDU | E21: 26.4.002093 | F21: 800229.V | G21: 112425/2.V | H21: 12440 | I21: 1 | J21: 5021701 | K21: 26.4.002100 | L21: 800223.V | M21: 112460/2.V | N21: 12320 | O21: EC | P21: PU | Q21: SEL | R21: SI | S21: SE | T21: U1 | U21: FL | W21: SMS | X21: EX2 | Z21: TH | AA21: UTPA | AB21: UTMAN | AC21: UE | AD21: RX | AE21: LIMAB | AF21: IF1 | AG21: IF2 | AH21: PM | AI21: BA
A22: 20 | B22: 5021701 | C22: 609.600mm / 32.200mm | D22: DNV-ST-F101-2021 x 450 SFDU | E22: 26.4.002105 | F22: 800229.V | G22: 112425/1.V | H22: 12340 | I22: 1 | J22: 5021701 | K22: 26.4.002101 | L22: 974058.V | M22: 112412/1.V | N22: 12320 | O22: EC | P22: PU | Q22: SEL | R22: SI | S22: SE | T22: U1 | U22: FL | W22: SMS | X22: EX2 | Z22: TH | AA22: UTPA | AB22: UTMAN | AC22: UE | AD22: RX | AE22: LIMAB | AF22: IF1 | AG22: IF2 | AH22: PM | AI22: BA
A23: 21 | B23: 5021701 | C23: 609.600mm / 32.200mm | D23: DNV-ST-F101-2021 x 450 SFDU | E23: 26.4.002106 | F23: 800229.V | G23: 112422/2.V | H23: 12320 | I23: 1 | J23: 5021701 | K23: 26.4.002102 | L23: 974058.V | M23: 112411/2.V | N23: 12280 | O23: EC | P23: PU | Q23: SEL | R23: SI | S23: SE | T23: U1 | W23: SMS | X23: EX2 | Z23: TH | AA23: UTPA | AB23: UTMAN | AC23: UE | AD23: RX | AE23: LIMAB | AF23: IF1 | AG23: IF2 | AH23: PM | AI23: BA
A24: 22 | B24: 5021701 | C24: 609.600mm / 32.200mm | D24: DNV-ST-F101-2021 x 450 SFDU | E24: 26.4.002107 | F24: 800229.V | G24: 112423/2.V | H24: 12370 | I24: 1 | J24: 5021701 | K24: 26.4.008022 | L24: 780995.V | M24: 118312/1.V | N24: 12460 | O24: EC | P24: PU | Q24: SEL | R24: SI | S24: SE | T24: U1 | X24: EX2 | Z24: TH
A25: 23 | B25: 5021701 | C25: 609.600mm / 32.200mm | D25: DNV-ST-F101-2021 x 450 SFDU | E25: 26.4.002108 | F25: 800229.V | G25: 112424/2.V | H25: 12330 | I25: 1 | J25: 5021701 | K25: 26.4.002104 | L25: 800229.V | M25: 112429/1.V | N25: 12430 | O25: EC | P25: PU | Q25: SEL | R25: SI | S25: SE | T25: U1 | W25: SMS | X25: EX2 | Z25: TH | AA25: UTPA | AB25: UTMAN | AC25: UE | AD25: RX | AE25: LIMAB | AF25: IF1 | AG25: IF2 | AH25: PM | AI25: BA
A26: 24 | B26: 5021701 | C26: 609.600mm / 32.200mm | D26: DNV-ST-F101-2021 x 450 SFDU | E26: 26.4.002109 | F26: 800229.V | G26: 112428/2.V | H26: 12470 | I26: 1 | J26: 5021701 | K26: 26.4.002105 | L26: 800229.V | M26: 112425/1.V | N26: 12340 | O26: EC | P26: PU | Q26: SEL | R26: SI | S26: SE | T26: U1 | W26: SMS | X26: EX2 | Z26: TH | AA26: UTPA | AB26: UTMAN | AC26: UE | AD26: RX | AE26: LIMAB | AF26: IF1 | AG26: IF2 | AH26: PM | AI26: BA
A27: 25 | B27: 5021701 | C27: 609.600mm / 32.200mm | D27: DNV-ST-F101-2021 x 450 SFDU | E27: 26.4.002110 | F27: 800229.V | G27: 112423/1.V | H27: 12300 | I27: 1 | J27: 5021701 | K27: 26.4.002106 | L27: 800229.V | M27: 112422/2.V | N27: 12320 | O27: EC | P27: PU | Q27: SEL | R27: SI | S27: SE | T27: U1 | W27: SMS | X27: EX2 | Z27: TH | AA27: UTPA | AB27: UTMAN | AC27: UE | AD27: RX | AE27: LIMAB | AF27: IF1 | AG27: IF2 | AH27: PM | AI27: BA
A28: 26 | B28: 5021701 | C28: 609.600mm / 32.200mm | D28: DNV-ST-F101-2021 x 450 SFDU | E28: 26.4.002111 | F28: 800229.V | G28: 112431/1.V | H28: 12440 | I28: 1 | J28: 5021701 | K28: 26.4.002116 | L28: 800233.V | M28: 112485/2.V | N28: 12020 | O28: EC | P28: PU | Q28: SEL | R28: SI | S28: SE | T28: U1 | W28: SMS | X28: EX2 | Z28: TH | AA28: UTPA | AB28: UTMAN | AC28: UE | AD28: RX | AE28: LIMAB | AF28: IF1 | AG28: IF2 | AH28: PM | AI28: BA
A29: 27 | B29: 5021701 | C29: 609.600mm / 32.200mm | D29: DNV-ST-F101-2021 x 450 SFDU | E29: 26.4.002112 | F29: 800229.V | G29: 112428/1.V | H29: 12440 | I29: 1 | J29: 5021701 | K29: 26.4.002095 | L29: 974058.V | M29: 112411/1.V | N29: 12460 | O29: EC | P29: PU | Q29: SEL | R29: SI | S29: SE | T29: U1
A30: 28 | B30: 5021701 | C30: 609.600mm / 32.200mm | D30: DNV-ST-F101-2021 x 450 SFDU | E30: 26.4.002113 | F30: 800229.V | G30: 112429/2.V | H30: 12470 | I30: 1 | J30: 5021701 | K30: 26.4.002094 | L30: 800229.V | M30: 112430/1.V | N30: 11360 | O30: EC | P30: PU | Q30: SEL | R30: SI | S30: SE | T30: U1 | W30: SMS | X30: EX2 | Z30: TH | AA30: UTPA | AB30: UTMAN | AC30: UE
A31: 29 | B31: 5021701 | C31: 609.600mm / 32.200mm | D31: DNV-ST-F101-2021 x 450 SFDU | E31: 26.4.002114 | F31: 800233.V | G31: 112487/1.V | H31: 12450 | I31: 1 | J31: 5021701 | K31: 26.4.002112 | L31: 800229.V | M31: 112428/1.V | N31: 12040 | O31: EC | P31: PU | Q31: SEL | R31: SI | S31: SE | T31: U1 | U31: FL | W31: SMS | X31: EX2 | Z31: TH | AA31: UTPA | AB31: UTMAN | AC31: UE | AD31: RX | AE31: LIMAB | AF31: IF1 | AG31: IF2 | AH31: PM | AI31: BA
A32: 30 | B32: 5021701 | C32: 609.600mm / 32.200mm | D32: DNV-ST-F101-2021 x 450 SFDU | E32: 26.4.002099 | F32: 800223.V | G32: 112459/1.V | H32: 12460 | I32: 1 | J32: 5021701 | K32: 26.4.002149 | L32: 800233.V | M32: 112483/2.V | N32: 12430 | O32: EC | P32: PU | Q32: SEL | R32: SI | S32: SE | T32: U1 | W32: SMS | X32: EX2 | Z32: TH | AA32: UTPA | AB32: UTMAN | AC32: UE | AD32: RX | AE32: LIMAB | AF32: IF1 | AG32: IF2 | AH32: PM | AI32: BA
A33: 31 | B33: 5021701 | C33: 609.600mm / 32.200mm | D33: DNV-ST-F101-2021 x 450 SFDU | E33: 26.4.002116 | F33: 800233.V | G33: 112485/2.V | H33: 12020 | I33: 1 | J33: 5021701 | K33: 26.4.002111 | L33: 800229.V | M33: 112431/1.V | N33: 12040 | O33: EC | P33: PU | Q33: SEL | R33: SI | S33: SE | T33: U1 | W33: SMS | X33: EX2 | Z33: TH | AA33: UTPA | AB33: UTMAN | AC33: UE | AD33: RX | AE33: LIMAB | AF33: IF1 | AG33: IF2 | AH33: PM | AI33: BA
A34: 32 | B34: 5021701 | C34: 609.600mm / 32.200mm | D34: DNV-ST-F101-2021 x 450 SFDU | E34: 26.4.002117 | F34: 800233.V | G34: 112490/1.V | H34: 12020 | I34: 1 | J34: 5021701 | K34: 26.4.002114 | L34: 800233.V | M34: 112487/1.V | N34: 12430 | O34: EC | P34: PU | Q34: SEL | R34: SI | S34: SE | T34: U1 | W34: SMS | X34: EX2 | Z34: TH | AA34: UTPA | AB34: UTMAN | AC34: UE | AD34: RX | AE34: LIMAB | AF34: IF1 | AG34: IF2 | AH34: PM | AI34: BA
A35: 33 | B35: 5021701 | C35: 609.600mm / 32.200mm | D35: DNV-ST-F101-2021 x 450 SFDU | E35: 26.4.002118 | F35: 800232.V | G35: 112444/2.V | H35: 12470 | I35: 1 | J35: 5021701 | K35: 26.4.002115 | L35: 800233.V | M35: 112488/2.V | N35: 12440 | O35: EC | P35: PU | Q35: SEL | R35: SI | S35: SE | T35: U1 | W35: SMS | X35: EX2 | Z35: TH | AA35: UTPA | AB35: UTMAN | AC35: UE | AD35: RX | AE35: LIMAB | AF35: IF1 | AG35: IF2 | AH35: PM | AI35: BA
A36: 34 | B36: 5021701 | C36: 609.600mm / 32.200mm | D36: DNV-ST-F101-2021 x 450 SFDU | E36: 26.4.002119 | F36: 800233.V | G36: 112483/1.V | H36: 12450 | I36: 1 | J36: 5021701 | K36: 26.4.002241 | L36: 974058.V | M36: 112415/2.V | N36: 12440 | O36: EC | P36: PU | Q36: SEL | R36: SI | S36: SE | T36: U1 | W36: SMS | X36: EX2 | Z36: TH | AA36: UTPA | AB36: UTMAN | AC36: UE | AD36: RX | AE36: LIMAB | AF36: IF1 | AG36: IF2 | AH36: PM | AI36: BA
A37: 35 | B37: 5021701 | C37: 609.600mm / 32.200mm | D37: DNV-ST-F101-2021 x 450 SFDU | E37: 26.4.002120 | F37: 800232.V | G37: 112437/2.V | H37: 12450 | I37: 1 | J37: 5021701 | K37: 26.4.002118 | L37: 800232.V | M37: 112444/2.V | N37: 12040 | O37: EC | P37: PU | Q37: SEL | R37: SI | S37: SE | T37: U1 | W37: SMS | X37: EX2 | Z37: TH | AA37: UTPA | AB37: UTMAN | AC37: UE | AD37: RX | AE37: LIMAB | AF37: IF1 | AG37: IF2 | AH37: PM | AI37: BA
A38: 36 | B38: 5021701 | C38: 609.600mm / 32.200mm | D38: DNV-ST-F101-2021 x 450 SFDU | E38: 26.4.002121 | F38: 800232.V | G38: 112441/2.V | H38: 12450 | I38: 1 | J38: 5021701 | K38: 26.4.002119 | L38: 800233.V | M38: 112483/1.V | N38: 12430 | O38: EC | P38: PU | Q38: SEL | R38: SI | S38: SE | T38: U1 | W38: SMS | X38: EX2 | Z38: TH | AA38: UTPA | AB38: UTMAN | AC38: UE | AD38: RX | AE38: LIMAB | AF38: IF1 | AG38: IF2 | AH38: PM | AI38: BA
A39: 37 | B39: 5021701 | C39: 609.600mm / 32.200mm | D39: DNV-ST-F101-2021 x 450 SFDU | E39: 26.4.002122 | F39: 800232.V | G39: 112434/2.V | H39: 12450 | I39: 1 | J39: 5021701 | K39: 26.4.002120 | L39: 800232.V | M39: 112437/2.V | N39: 12330 | O39: EC | P39: PU | Q39: SEL | R39: SI | S39: SE | T39: U1 | W39: SMS | X39: EX2 | Z39: TH | AA39: UTPA | AB39: UTMAN | AC39: UE | AD39: RX | AE39: LIMAB | AF39: IF1 | AG39: IF2 | AH39: PM | AI39: BA
A40: 38 | B40: 5021701 | C40: 609.600mm / 32.200mm | D40: DNV-ST-F101-2021 x 450 SFDU | E40: 26.4.002123 | F40: 800232.V | G40: 112437/1.V | H40: 12450 | I40: 1 | J40: 5021701 | K40: 26.4.002121 | L40: 800232.V | M40: 112441/2.V | N40: 12180 | O40: EC | P40: PU | Q40: SEL | R40: SI | S40: SE | T40: U1 | W40: SMS | X40: EX2 | Z40: TH | AA40: UTPA | AB40: UTMAN | AC40: UE | AD40: RX | AE40: LIMAB | AF40: IF1 | AG40: IF2 | AH40: PM | AI40: BA
...

Sheet Pivot
B4: PO 5021701 | J4: PO 5021701 Totale | K4: Totale complessivo
B5: 780325.V | C5: 800222.V | D5: 800223.V | E5: 800229.V | F5: 800232.V | G5: 800233.V | H5: 974058.V | I5: 974062.V
A6: ITP Steps.
A7: Incoming Plate | B7: 28 | C7: 15 | D7: 21 | E7: 21 | F7: 25 | G7: 16 | H7: 18 | I7: 26 | J7: 170 | K7: 170
A8: Pipe Forming | B8: 28 | C8: 15 | D8: 21 | E8: 21 | F8: 25 | G8: 16 | H8: 18 | I8: 26 | J8: 170 | K8: 170
A9: Tack Welding | B9: 28 | C9: 15 | D9: 21 | E9: 21 | F9: 25 | G9: 16 | H9: 18 | I9: 26 | J9: 170 | K9: 170
A10: ID SAWL | B10: 28 | C10: 15 | D10: 21 | E10: 21 | F10: 25 | G10: 16 | H10: 18 | I10: 26 | J10: 170 | K10: 170
A11: OD SAWL | B11: 28 | C11: 15 | D11: 21 | E11: 21 | F11: 25 | G11: 16 | H11: 18 | I11: 26 | J11: 170 | K11: 170
A12: AUT1 | B12: 28 | C12: 15 | D12: 21 | E12: 21 | F12: 25 | G12: 16 | H12: 18 | I12: 26 | J12: 170 | K12: 170
A13: Fluoroscopic | D13: 3 | E13: 1 | F13: 1 | G13: 1 | H13: 4 | I13: 2 | J13: 12 | K13: 12
A14: Welding Repair | C14: 2 | E14: 1 | H14: 1 | J14: 4 | K14: 4
A15: MCE1 | B15: 28 | C15: 13 | D15: 21 | E15: 20 | F15: 24 | G15: 16 | H15: 16 | I15: 26 | J15: 164 | K15: 164
A16: MCE2
A17: MCE Inspection | B17: 28 | C17: 13 | D17: 21 | E17: 20 | F17: 24 | G17: 16 | H17: 16 | I17: 26 | J17: 164 | K17: 164
A18: Straighness Re-work | B18: 1 | D18: 2 | E18: 2 | H18: 1 | J18: 6 | K18: 6
A19: Hydro Test | B19: 27 | C19: 13 | D19: 19 | E19: 18 | F19: 24 | G19: 16 | H19: 15 | I19: 26 | J19: 158 | K19: 158
A20: AUT2
A21: Phase Arr. | B21: 27 | C21: 13 | D21: 19 | E21: 18 | F21: 24 | G21: 16 | H21: 15 | I21: 26 | J21: 158 | K21: 158
A22: MUT_ | B22: 27 | C22: 13 | D22: 19 | E22: 18 | F22: 24 | G22: 16 | H22: 15 | I22: 26 | J22: 158 | K22: 158
A23: End UT | B23: 27 | C23: 13 | D23: 19 | E23: 17 | F23: 24 | G23: 16 | H23: 15 | I23: 26 | J23: 157 | K23: 157
A24: X-Ray | B24: 27 | C24: 13 | D24: 19 | E24: 16 | F24: 24 | G24: 16 | H24: 15 | I24: 26 | J24: 156 | K24: 156
A25: OoR Pipe Body | B25: 27 | C25: 13 | D25: 19 | E25: 16 | F25: 24 | G25: 16 | H25: 15 | I25: 26 | J25: 156 | K25: 156
A26: Dimensional 1 | B26: 25 | C26: 12 | D26: 18 | E26: 15 | F26: 24 | G26: 16 | H26: 15 | I26: 25 | J26: 150 | K26: 150
A27: Dimensional 2 | B27: 25 | C27: 12 | D27: 18 | E27: 15 | F27: 24 | G27: 16 | H27: 14 | I27: 25 | J27: 149 | K27: 149
A28: MPI | B28: 25 | C28: 12 | D28: 18 | E28: 15 | F28: 24 | G28: 16 | H28: 14 | I28: 25 | J28: 149 | K28: 149
A29: UT DHC | B29: 25 | C29: 12 | D29: 17 | E29: 15 | F29: 24 | G29: 16 | H29: 14 | I29: 24 | J29: 147 | K29: 147
A30: Final Marking and Weighing | B30: 25 | C30: 12 | D30: 18 | E30: 15 | F30: 24 | G30: 16 | H30: 14 | I30: 25 | J30: 149 | K30: 149

Sheet Chart

Sheet Repair
B2: 24OD x 1.268WT
B3: REPAIR TABLE
B4: DATE | C4: Shift | D4: Pipe Nº | E4: Defect | F4: Pipe Position (mm) | G4: Extension (mm) | H4: Remarks
B5: 46064 | C5: 1 | D5: 26.4.2089 | E5: Weld heigh bead below the specified | F5: 1200 | G5: 300
B6: 46072 | C6: 1 | D6: 26.4.2205 | E6: Slag Inclusion | F6: 1450 | G6: 100
B7: 46073 | C7: 1 | D7: 26.4.2207 | E7: Underfill | F7: 5510 | G7: 130
B8: 46074 | C8: 1 | D8: 26.4.2252 | E8: Stop/Start | F8: 2320 | G8: 200
B9: 46181 | C9: 1 | D9: 26.4.7866 | E9: Weld Fail | F9: 4600 | G9: 200
B10: 46181 | C10: 3 | D10: 26.4.7838 | E10: Weld Leak | F10: 2500 | G10: 200
B11: 46182 | C11: 1 | D11: 26.4.7840 | E11: Slag Inclusion | F11: 3360/5850 | G11: 150/100
B12: 46183 | C12: 1 | D12: 26.4.7888 | E12: Stop/Start | F12: 8190 | G12: 200
B13: 46183 | C13: 1 | D13: 26.4.7841 | E13: Stop/Start | F13: 2024 | G13: 200
B14: 46183 | C14: 1 | D14: 26.4.7986 | E14: Stop/Start | F14: 9770 | G14: 200
B15: 46183 | C15: 1 | D15: 26.4.7955 | E15: Underfill | F15: 3190 | G15: 150
B16: 46183 | C16: 1 | D16: 26.4.8007 | E16: Underfill | F16: 9100 | G16: 150
B17: 46183 | C17: 1 | D17: 26.4.8071 | E17: Stop/Start | F17: 2830 | G17: 200
B18: 46183 | C18: 3 | D18: 26.4.8118 | E18: Stop/Start | F18: 7340 | G18: 180
B19: 46183 | C19: 3 | D19: 26.4.8117 | E19: Stop/Start | F19: 3930 | G19: 170
B20: 46184 | C20: 3 | D20: 26.4.8219 | E20: Stop/Start | F20: 11900 | G20: 200
B21: 46185 | C21: 1 | D21: 24.6.8204 | E21: Stop/Start | F21: 6720 | G21: 250
B22: 46185 | C22: 3 | D22: 24.6.8231 | E22: Stop/Start | F22: 5900 | G22: 100

Sheet Rejection
B1: 24OD x 1.268WT
B2: REJECTION TABLE
B3: DATE | C3: Shift | D3: Pipe Nº | E3: Defect | F3: Remarks
B4: 46064 | C4: 1 | D4: 26.4.2095 | E4: Burn Through | F4: MPQT Pipe (NCR-001)
B5: 46076 | C5: 1 | D5: 26.4.2094 | E5: Pore | F5: 2350x50mm
B6: 46076 | C6: 1 | D6: 26.4.2250 | E6: WT Below Spec | F6: 8100x640mm
B7: 46091 | C7: 1 | D7: 26.4.2114 | E7: Heated over 3 times | F7: 3LPP Tenaris Internal Trials
B8: 46091 | C8: 1 | D8: 26.4.2185 | E8: Heated over 3 times | F8: 3LPP Tenaris Internal Trials
B9: 46091 | C9: 1 | D9: 26.4.2107 | E9: Heated over 3 times | F9: 3LPP Tenaris Internal Trials
B10: 46091 | C10: 1 | D10: 26.4.2145 | E10: Heated over 3 times | F10: 3LPP Tenaris Internal Trials
B11: 46091 | C11: 1 | D11: 26.4.2148 | E11: Heated over 3 times | F11: 3LPP Tenaris Internal Trials
B12: 46091 | C12: 1 | D12: 26.4.2144 | E12: Heated over 3 times | F12: 3LPP Tenaris Internal Trials
B13: 46091 | C13: 1 | D13: 26.4.2149 | E13: Heated over 3 times | F13: 3LPP Tenaris Internal Trials
B14: 46091 | C14: 1 | D14: 26.4.2180 | E14: Heated over 3 times | F14: 3LPP Tenaris Internal Trials
B15: 46091 | C15: 1 | D15: 26.4.2115 | E15: Heated over 3 times | F15: 3LPP Tenaris Internal Trials
... B23: 46184 | C23: 2 | D23: 26.4.8113 | E23: Tack Weld Parameter | F23: (NCR-009)
B24: 46185 | C24: 1 | D24: 26.4.7952 | E24: MCE Mark
B25: 46186 | C25: 3 | D25: 26.4.7773 | E25: Wall TKS Below the Spec.
